Traceback (most recent call last):
  File "/home/jfhlewyee/Software/anaconda3/envs/book/lib/python3.8/site-packages/jupyter_cache/executors/utils.py", line 51, in single_nb_execution
    executenb(
  File "/home/jfhlewyee/Software/anaconda3/envs/book/lib/python3.8/site-packages/nbclient/client.py", line 1077, in execute
    return NotebookClient(nb=nb, resources=resources, km=km, **kwargs).execute()
  File "/home/jfhlewyee/Software/anaconda3/envs/book/lib/python3.8/site-packages/nbclient/util.py", line 74, in wrapped
    return just_run(coro(*args, **kwargs))
  File "/home/jfhlewyee/Software/anaconda3/envs/book/lib/python3.8/site-packages/nbclient/util.py", line 53, in just_run
    return loop.run_until_complete(coro)
  File "/home/jfhlewyee/Software/anaconda3/envs/book/lib/python3.8/asyncio/base_events.py", line 616, in run_until_complete
    return future.result()
  File "/home/jfhlewyee/Software/anaconda3/envs/book/lib/python3.8/site-packages/nbclient/client.py", line 526, in async_execute
    await self.async_execute_cell(
  File "/home/jfhlewyee/Software/anaconda3/envs/book/lib/python3.8/site-packages/nbclient/client.py", line 822, in async_execute_cell
    self._check_raise_for_error(cell, exec_reply)
  File "/home/jfhlewyee/Software/anaconda3/envs/book/lib/python3.8/site-packages/nbclient/client.py", line 730, in _check_raise_for_error
    raise CellExecutionError.from_cell_and_msg(cell, exec_reply['content'])
nbclient.exceptions.CellExecutionError: An error occurred while executing the following cell:
------------------
import psi4
psi4.set_memory("2 gb")
psi4.geometry("""
0 1
   N       -4.84638        1.76109        0.00000
   N       -3.46888        1.78415        0.00000
   O       -2.82385        2.93169       -0.00000
   O       -2.85055        0.76276        0.00000
   O       -5.46471        2.78248        0.00000
   O       -5.49141        0.61355        0.00000
""")
n2o4,wfn=psi4.opt("HF/aug-cc-pvdz", return_wfn=True)
print(n2o4)
------------------

[0;31m---------------------------------------------------------------------------[0m
[0;31mModuleNotFoundError[0m                       Traceback (most recent call last)
[0;32m<ipython-input-1-1e671bb0dca4>[0m in [0;36m<module>[0;34m[0m
[0;32m----> 1[0;31m [0;32mimport[0m [0mpsi4[0m[0;34m[0m[0;34m[0m[0m
[0m[1;32m      2[0m [0mpsi4[0m[0;34m.[0m[0mset_memory[0m[0;34m([0m[0;34m"2 gb"[0m[0;34m)[0m[0;34m[0m[0;34m[0m[0m
[1;32m      3[0m psi4.geometry("""
[1;32m      4[0m [0;36m0[0m [0;36m1[0m[0;34m[0m[0;34m[0m[0m
[1;32m      5[0m    [0mN[0m       [0;34m-[0m[0;36m4.84638[0m        [0;36m1.76109[0m        [0;36m0.00000[0m[0;34m[0m[0;34m[0m[0m

[0;31mModuleNotFoundError[0m: No module named 'psi4'
ModuleNotFoundError: No module named 'psi4'

