Traceback (most recent call last):
  File "/home/jfhlewyee/anaconda3/envs/jb/lib/python3.9/site-packages/nbclient/client.py", line 730, in _async_poll_for_reply
    msg = await ensure_async(self.kc.shell_channel.get_msg(timeout=new_timeout))
  File "/home/jfhlewyee/anaconda3/envs/jb/lib/python3.9/site-packages/nbclient/util.py", line 96, in ensure_async
    result = await obj
  File "/home/jfhlewyee/anaconda3/envs/jb/lib/python3.9/site-packages/jupyter_client/channels.py", line 230, in get_msg
    raise Empty
_queue.Empty

During handling of the above exception, another exception occurred:

Traceback (most recent call last):
  File "/home/jfhlewyee/anaconda3/envs/jb/lib/python3.9/site-packages/jupyter_cache/executors/utils.py", line 51, in single_nb_execution
    executenb(
  File "/home/jfhlewyee/anaconda3/envs/jb/lib/python3.9/site-packages/nbclient/client.py", line 1204, in execute
    return NotebookClient(nb=nb, resources=resources, km=km, **kwargs).execute()
  File "/home/jfhlewyee/anaconda3/envs/jb/lib/python3.9/site-packages/nbclient/util.py", line 84, in wrapped
    return just_run(coro(*args, **kwargs))
  File "/home/jfhlewyee/anaconda3/envs/jb/lib/python3.9/site-packages/nbclient/util.py", line 62, in just_run
    return loop.run_until_complete(coro)
  File "/home/jfhlewyee/anaconda3/envs/jb/lib/python3.9/asyncio/base_events.py", line 647, in run_until_complete
    return future.result()
  File "/home/jfhlewyee/anaconda3/envs/jb/lib/python3.9/site-packages/nbclient/client.py", line 663, in async_execute
    await self.async_execute_cell(
  File "/home/jfhlewyee/anaconda3/envs/jb/lib/python3.9/site-packages/nbclient/client.py", line 949, in async_execute_cell
    exec_reply = await self.task_poll_for_reply
  File "/home/jfhlewyee/anaconda3/envs/jb/lib/python3.9/site-packages/nbclient/client.py", line 754, in _async_poll_for_reply
    await self._async_handle_timeout(timeout, cell)
  File "/home/jfhlewyee/anaconda3/envs/jb/lib/python3.9/site-packages/nbclient/client.py", line 801, in _async_handle_timeout
    raise CellTimeoutError.error_from_timeout_and_cell(
nbclient.exceptions.CellTimeoutError: A cell timed out while it was being executed, after 30 seconds.
The message was: Cell execution timed out.
Here is a preview of the cell contents:
-------------------
['N2O4 = pyscf.gto.Mole(atom="""', '   N       -4.84638        1.76109        0.00000', '   N       -3.46888        1.78415        0.00000', '   O       -2.82385        2.93169       -0.00000', '   O       -2.85055        0.76276        0.00000']
...
['N2O4_eq = optimize(rks)', '', 'rks = dft.RKS(N2O4_eq)', 'rks.xc = "B3LYP"', 'n2o4 = rks.kernel()']
-------------------

