Traceback (most recent call last):
  File "/home/jfhlewyee/anaconda3/envs/book/lib/python3.7/site-packages/jupyter_cache/executors/utils.py", line 56, in single_nb_execution
    record_timing=False,
  File "/home/jfhlewyee/anaconda3/envs/book/lib/python3.7/site-packages/nbclient/client.py", line 1087, in execute
    return NotebookClient(nb=nb, resources=resources, km=km, **kwargs).execute()
  File "/home/jfhlewyee/anaconda3/envs/book/lib/python3.7/site-packages/nbclient/util.py", line 74, in wrapped
    return just_run(coro(*args, **kwargs))
  File "/home/jfhlewyee/anaconda3/envs/book/lib/python3.7/site-packages/nbclient/util.py", line 53, in just_run
    return loop.run_until_complete(coro)
  File "/home/jfhlewyee/anaconda3/envs/book/lib/python3.7/asyncio/base_events.py", line 587, in run_until_complete
    return future.result()
  File "/home/jfhlewyee/anaconda3/envs/book/lib/python3.7/site-packages/nbclient/client.py", line 541, in async_execute
    cell, index, execution_count=self.code_cells_executed + 1
  File "/home/jfhlewyee/anaconda3/envs/book/lib/python3.7/site-packages/nbclient/client.py", line 832, in async_execute_cell
    self._check_raise_for_error(cell, exec_reply)
  File "/home/jfhlewyee/anaconda3/envs/book/lib/python3.7/site-packages/nbclient/client.py", line 740, in _check_raise_for_error
    raise CellExecutionError.from_cell_and_msg(cell, exec_reply['content'])
nbclient.exceptions.CellExecutionError: An error occurred while executing the following cell:
------------------
#Grafica

import scipy.special as sp
import numpy as np
from mpl_toolkits.mplot3d import Axes3D
import numpy as np
import matplotlib.pyplot as plt

ml=0
l=1

theta = np.linspace(0,np.pi,100)
phi = np.linspace(0,2*np.pi,100)
THETA,PHI=np.meshgrid(theta,phi)

R=np.abs(sp.sph_harm(ml,l,PHI,THETA))

X = R * np.sin(THETA) * np.cos(PHI)
Y = R * np.sin(THETA) * np.sin(PHI)
Z = R * np.cos(THETA)

fig = plt.figure()
ax = plt.gca(projection='3d')
ax.plot_surface(X, Y, Z,cmap='YlOrRd')
#ax.set_xlim(-0.4,0.4)
#ax.set_ylim(-0.4,0.4)
#ax.set_zlim(-0.4,0.4)
ax.set_title("$\Psi$")
plt.show()

R=np.power(R,2.0)

X = R * np.sin(THETA) * np.cos(PHI)
Y = R * np.sin(THETA) * np.sin(PHI)
Z = R * np.cos(THETA)

fig = plt.figure()
ax = plt.gca(projection='3d')
ax.plot_surface(X, Y, Z,cmap='YlOrRd')
ax.set_xlim(-0.2,0.2)
ax.set_ylim(-0.2,0.2)
ax.set_zlim(-0.2,0.2)
ax.set_title("$\Psi^2$")
plt.show()
------------------

[0;31m---------------------------------------------------------------------------[0m
[0;31mModuleNotFoundError[0m                       Traceback (most recent call last)
[0;32m<ipython-input-2-912ed0bc15ad>[0m in [0;36m<module>[0;34m[0m
[1;32m      1[0m [0;31m#Grafica[0m[0;34m[0m[0;34m[0m[0;34m[0m[0m
[1;32m      2[0m [0;34m[0m[0m
[0;32m----> 3[0;31m [0;32mimport[0m [0mscipy[0m[0;34m.[0m[0mspecial[0m [0;32mas[0m [0msp[0m[0;34m[0m[0;34m[0m[0m
[0m[1;32m      4[0m [0;32mimport[0m [0mnumpy[0m [0;32mas[0m [0mnp[0m[0;34m[0m[0;34m[0m[0m
[1;32m      5[0m [0;32mfrom[0m [0mmpl_toolkits[0m[0;34m.[0m[0mmplot3d[0m [0;32mimport[0m [0mAxes3D[0m[0;34m[0m[0;34m[0m[0m

[0;31mModuleNotFoundError[0m: No module named 'scipy'
ModuleNotFoundError: No module named 'scipy'

